Workbook

Sheet DECISION
A1: ARIANE II : Polytech Gombert 2026 / U07
A2: DECISIONS Firme 3
A3: 2/22/2026 12:40:46 PM
B5: Périodes | D5: -3 | E5: -2 | F5: -1 | G5: 0 | H5: 1 | I5: 2 | J5: 3 | K5: 4 | L5: 5 | M5: 6
B7: PRODUITS / ski Elite
A8: D032 | B8: Prix | D8: 200.00 | E8: 200.00 | F8: 200.00 | G8: 200.00 | H8: 200.00 | I8: 200.00 | J8: 250.00 | K8: 240.00 | L8: 250.00 | M8: 260.00
A9: D033 | B9: Production (KU) | D9: 200 | E9: 200 | F9: 200 | G9: 200 | H9: 180 | I9: 120 | J9: 122 | K9: 103 | L9: 125 | M9: 120
A10: D034 | B10: Publicité (K€) | D10: 500 | E10: 1000 | F10: 600 | G10: 600 | H10: 500 | I10: 500 | J10: 400 | K10: 400 | L10: 400 | M10: 700
B11: ski 2000
A12: D039 | B12: Prix | D12: 0.00 | E12: 0.00 | F12: 0.00 | G12: 0.00 | H12: 170.00 | I12: 170.00 | J12: 190.00 | K12: 190.00 | L12: 200.00 | M12: 210.00
A13: D040 | B13: Production (KU) | D13: 0 | E13: 0 | F13: 0 | G13: 0 | H13: 20 | I13: 90 | J13: 80 | K13: 104 | L13: 106 | M13: 79
A14: D041 | B14: Publicité (K€) | D14: 0 | E14: 0 | F14: 0 | G14: 0 | H14: 200 | I14: 300 | J14: 200 | K14: 200 | L14: 400 | M14: 900
A15: D042 | B15: Qualité (0 … 100) | D15: 0 | E15: 0 | F15: 0 | G15: 0 | H15: 30 | I15: 30 | J15: 30 | K15: 30 | L15: 30 | M15: 30
B16: Raquette +
A17: D053 | B17: Prix | D17: 0.00 | E17: 0.00 | F17: 0.00 | G17: 0.00 | H17: 0.00 | I17: 80.00 | J17: 170.00 | K17: 169.00 | L17: 170.00 | M17: 170.00
A18: D054 | B18: Production (KU) | D18: 0 | E18: 0 | F18: 0 | G18: 0 | H18: 0 | I18: 37 | J18: 34 | K18: 58 | L18: 34 | M18: 50
A19: D055 | B19: Publicité (K€) | D19: 0 | E19: 0 | F19: 0 | G19: 0 | H19: 0 | I19: 200 | J19: 400 | K19: 400 | L19: 300 | M19: 600
B20: ETUDES DE MARCHE
A21: D024 | B21: Etude Marché / ski (O/N) | D21: -N- | E21: -N- | F21: -N- | G21: -N- | H21: -N- | I21: -N- | J21: -N- | K21: -N- | L21: OUI | M21: -N-
A22: D025 | B22: Etude Marché / raquette (O/N) | D22: -N- | E22: -N- | F22: -N- | G22: -N- | H22: -N- | I22: -N- | J22: -N- | K22: OUI | L22: -N- | M22: -N-
A23: D091 | B23: Comptabilité Analytique (O/N) | D23: -N- | E23: -N- | F23: -N- | G23: -N- | H23: OUI | I23: OUI | J23: OUI | K23: OUI | L23: OUI | M23: -N-
B24: PRODUCTION
A25: D013 | B25: Recherche et Dev. (K€) | D25: 100 | E25: 100 | F25: 100 | G25: 100 | H25: 100 | I25: 200 | J25: 200 | K25: 200 | L25: 200 | M25: 200
A26: D016 | B26: Achat/Vente machines MX (Nb) | D26: 0 | E26: 0 | F26: 0 | G26: 0 | H26: 0 | I26: 0 | J26: 1 | K26: 0 | L26: 1 | M26: 0
A27: D017 | B27: Achat machines MY (Nb) | D27: 0 | E27: 0 | F27: 0 | G27: 0 | H27: 0 | I27: 1 | J27: 0 | K27: 1 | L27: 0 | M27: 0
B28: Approvisionnement
A29: D084 | B29: Pour le fournisseur (1-6) | D29: 0 | E29: 0 | F29: 0 | G29: 0 | H29: 0 | I29: 0 | J29: 0 | K29: 0 | L29: 0 | M29: 0
A30: D051 | B30: Delai paiement (Nb Mois)(0-2) | D30: 0 | E30: 0 | F30: 0 | G30: 0 | H30: 0 | I30: 0 | J30: 0 | K30: 0 | L30: 0 | M30: 0
A31: D014 | B31: Achats Mat.Prem.Fibre (KU) | D31: 3300 | E31: 3300 | F31: 3000 | G31: 3000 | H31: 1900 | I31: 2800 | J31: 4200 | K31: 900 | L31: 2700 | M31: 2400
A32: D094 | B32: % Fibre recyclée (0-100) | D32: 0 | E32: 0 | F32: 0 | G32: 0 | H32: 0 | I32: 0 | J32: 10 | K32: 10 | L32: 10 | M32: 10
A33: D015 | B33: Achats Mat.Prem.Résine (KU) | D33: 750 | E33: 750 | F33: 600 | G33: 900 | H33: 900 | I33: 2900 | J33: 600 | K33: 2100 | L33: 2500 | M33: 1700
A34: D095 | B34: % Resine recyclée (0-100) | D34: 0 | E34: 0 | F34: 0 | G34: 0 | H34: 0 | I34: 0 | J34: 30 | K34: 30 | L34: 30 | M34: 30
A35: D085 | B35: Pour le fournisseur (1-6) | D35: 0 | E35: 0 | F35: 0 | G35: 0 | H35: 0 | I35: 0 | J35: 0 | K35: 0 | L35: 0 | M35: 0
A36: D052 | B36: Delai paiement (Nb Mois)(0-2) | D36: 0 | E36: 0 | F36: 0 | G36: 0 | H36: 0 | I36: 0 | J36: 0 | K36: 0 | L36: 0 | M36: 0
A37: D064 | B37: Achats Mat.Prem.Fibre (KU) | D37: 0 | E37: 0 | F37: 0 | G37: 0 | H37: 0 | I37: 0 | J37: 0 | K37: 0 | L37: 0 | M37: 0
A38: D066 | B38: % Fibre recyclée (0-100) | D38: 0 | E38: 0 | F38: 0 | G38: 0 | H38: 0 | I38: 0 | J38: 0 | K38: 0 | L38: 0 | M38: 0
A39: D065 | B39: Achats Mat.Prem.Résine (KU) | D39: 0 | E39: 0 | F39: 0 | G39: 0 | H39: 0 | I39: 0 | J39: 0 | K39: 0 | L39: 0 | M39: 0
A40: D067 | B40: % Resine recyclée (0-100) | D40: 0 | E40: 0 | F40: 0 | G40: 0 | H40: 0 | I40: 0 | J40: 0 | K40: 0 | L40: 0 | M40: 0
B41: RESSOURCES HUMAINES
A42: D018 | B42: Embauche/Licenc.Ouvriers (Nb) | D42: 0 | E42: 0 | F42: 0 | G42: 0 | H42: 0 | I42: 0 | J42: 0 | K42: 60 | L42: 0 | M42: 0
...

Sheet RESULTAT
A1: ARIANE II : Polytech Gombert 2026 / U07
A2: RESULTATS des FIRMES Firme 3
A3: 2/22/2026 12:40:47 PM
B5: Périodes | D5: -3 | E5: -2 | F5: -1 | G5: 0 | H5: 1 | I5: 2 | J5: 3 | K5: 4 | L5: 5 | M5: 6
B8: PRODUITS
B10: Ventes | D10: 37500 | E10: 75606 | F10: 45486 | G10: 27559 | H10: 37820 | I10: 57189 | J10: 43450 | K10: 37198 | L10: 38932 | M10: 78817
B11: COUT DE PRODUCTION DES PRODUITS | D11: 29813 | E11: 60853 | F11: 37008 | G11: 22460 | H11: 30562 | I11: 48696 | J11: 29921 | K11: 25948 | L11: 28668 | M11: 53867
B12: Consommation Matières Premièr | D12: 17000 | E12: 17000 | F12: 17000 | G12: 17000 | H12: 16250 | I12: 15631 | J12: 15737 | K12: 16092 | L12: 22934 | M12: 17205
B13: Main d'oeuvre de production | D13: 9250 | E13: 9250 | F13: 9250 | G13: 9250 | H13: 9250 | I13: 11894 | J13: 11275 | K13: 12726 | L13: 12681 | M13: 11781
B14: Salaires Ouvriers | D14: 7500 | E14: 7500 | F14: 7500 | G14: 7500 | H14: 7500 | I14: 7500 | J14: 7500 | K14: 7950 | L14: 7950 | M14: 7950
B15: Heures Supplémentaires ouvrie | D15: 0 | E15: 0 | F15: 0 | G15: 0 | H15: 0 | I15: 2644 | J15: 2025 | K15: 2981 | L15: 2981 | M15: 2081
B16: Embauche/Licenciement | D16: 0 | E16: 0 | F16: 0 | G16: 0 | H16: 0 | I16: 0 | J16: 0 | K16: 45 | L16: 0 | M16: 0
B17: Intérimaires | D17: 0 | E17: 0 | F17: 0 | G17: 0 | H17: 0 | I17: 0 | J17: 0 | K17: 0 | L17: 0 | M17: 0
B18: Agents de Maîtrise | D18: 1750 | E18: 1750 | F18: 1750 | G18: 1750 | H18: 1750 | I18: 1750 | J18: 1750 | K18: 1750 | L18: 1750 | M18: 1750
B19: Coûts Variables de Production | D19: 5000 | E19: 5000 | F19: 5000 | G19: 5000 | H19: 5000 | I19: 5453 | J19: 4827 | K19: 5289 | L19: 4872 | M19: 4537
B20: Recherche et Développement | D20: 100 | E20: 100 | F20: 100 | G20: 100 | H20: 100 | I20: 200 | J20: 200 | K20: 200 | L20: 200 | M20: 200
B21: Dotation aux Amortissements | D21: 1250 | E21: 1250 | F21: 1250 | G21: 1250 | H21: 1250 | I21: 1350 | J21: 1475 | K21: 1575 | L21: 1700 | M21: 1700
... B31: Frais de Gestion | D31: 2000 | E31: 2000 | F31: 2000 | G31: 2000 | H31: 2000 | I31: 2000 | J31: 2000 | K31: 2000 | L31: 2000 | M31: 2000
B32: Frais Financiers | D32: 500 | E32: 1260 | F32: 250 | G32: -71 | H32: -300 | I32: -128 | J32: -88 | K32: -317 | L32: -41 | M32: 12 | O32: est-ce que R&D rentable si on baisse CVP
B33: Autres Charges / Produits | D33: 0 | E33: 0 | F33: 0 | G33: 0 | H33: 20 | I33: 2020 | J33: 2020 | K33: 3530 | L33: 2030 | M33: 2250
B34: RESULTAT OPERATIONNEL | D34: 2187 | E34: 7992 | F34: 3128 | G34: 70 | H34: 2338 | I34: 1102 | J34: 6097 | K34: 2537 | L34: 2676 | M34: 15987
B35: "+/- Value sur cessions d'acti" | D35: 0 | E35: 0 | F35: 0 | G35: 0 | H35: 0 | I35: 0 | J35: 0 | K35: 0 | L35: 0 | M35: 0
B36: Impôts | D36: 1094 | E36: 2637 | F36: 1032 | G36: 23 | H36: 772 | I36: 364 | J36: 2012 | K36: 837 | L36: 883 | M36: 5276
B37: Retour d'impôts | D37: 0 | E37: 0 | F37: 0 | G37: 0 | H37: 0 | I37: 0 | J37: 0 | K37: 0 | L37: 0 | M37: 0
B38: RESULTAT NET AVANT AFFECTATIO | D38: 1094 | E38: 5355 | F38: 2096 | G38: 47 | H38: 1566 | I38: 738 | J38: 4085 | K38: 1700 | L38: 1793 | M38: 10711
B39: Dividendes | D39: 0 | E39: 0 | F39: 0 | G39: 0 | H39: 0 | I39: 0 | J39: 0 | K39: 0 | L39: 0 | M39: 0
B40: RESULTAT NET MIS EN RESERVES | D40: 1094 | E40: 5355 | F40: 2096 | G40: 47 | H40: 1566 | I40: 738 | J40: 4085 | K40: 1700 | L40: 1793 | M40: 10711
B42: Bilan
B44: Machines MX | D44: 15000 | E44: 13750 | F44: 12500 | G44: 11250 | H44: 10000 | I44: 8750 | J44: 9875 | K44: 8500 | L44: 9500 | M44: 8000
B45: Machines MY | D45: 0 | E45: 0 | F45: 0 | G45: 0 | H45: 0 | I45: 1900 | J45: 1800 | K45: 3600 | L45: 3400 | M45: 3200
B46: Stocks Matières Premières | D46: 7875 | E46: 8313 | F46: 7063 | G46: 6188 | H46: 563 | I46: 2556 | J46: 9440 | K46: 973 | L46: 1383 | M46: 325
B47: Stocks Produits Finis | D47: 33400 | E47: 5147 | F47: 739 | G47: 10879 | H47: 12167 | I47: 0 | J47: 5592 | K47: 17526 | L47: 33246 | M47: 16802
B48: Créances clients | D48: 37500 | E48: 52924 | F48: 45486 | G48: 27559 | H48: 37820 | I48: 57189 | J48: 43450 | K48: 37198 | L48: 38154 | M48: 74088
B49: Trésorerie | D49: 1050 | E49: 46 | F49: 9800 | G49: 15134 | H49: 6527 | I49: 4419 | J49: 13355 | K49: 2628 | L49: 2428 | M49: 0
B50: TOTAL | D50: 94825 | E50: 80180 | F50: 75588 | G50: 71010 | H50: 67077 | I50: 74815 | J50: 83512 | K50: 70426 | L50: 88111 | M50: 102415
B51: CAPITAUX PROPRES | D51: 47387 | E51: 52742 | F51: 54838 | G51: 54885 | H51: 56452 | I51: 57190 | J51: 61275 | K51: 62974 | L51: 64767 | M51: 75479
B52: Capital Social | D52: 40000 | E52: 40000 | F52: 40000 | G52: 40000 | H52: 40000 | I52: 40000 | J52: 40000 | K52: 40000 | L52: 40000 | M52: 40000
B53: Primes d'émission | D53: 0 | E53: 0 | F53: 0 | G53: 0 | H53: 0 | I53: 0 | J53: 0 | K53: 0 | L53: 0 | M53: 0
B54: Réserves | D54: 6294 | E54: 7387 | F54: 12742 | G54: 14838 | H54: 14885 | I54: 16452 | J54: 17190 | K54: 21275 | L54: 22974 | M54: 24767
B55: Résultat net de la période | D55: 1094 | E55: 5355 | F55: 2096 | G55: 47 | H55: 1566 | I55: 738 | J55: 4085 | K55: 1700 | L55: 1793 | M55: 10711
...

Sheet ouvrier
B2: unité | C2: salaire | E2: production K | F2: ouvrier | G2: salaire | H2: salaire K | I2: embauche K
A3: 1ouvrier | B3: 200 | C3: 7500 | E3: 0.2 | F3: 1 | G3: 7500 | H3: =G3/1000 -> 7.5 | I3: =H3/10 -> 0.75
B4: 1 | C4: =C3/B3 -> 37.5 | E4: =F4 *E3 -> 12 | F4: 60 | G4: =$G$3 *F4 -> 450000 | H4: =G4/1000 -> 450 | I4: =H4/10 -> 45
E5: =F5 *E4 -> 4480 | F5: =G5/G3 -> 373.33333 | G5: =H5 *1000 -> 2800000 | H5: 2800 | I5: =H5/10 -> 280
B6: 50 | C6: =B6*C7 -> 2812.5
B7: 1 | C7: =C4*1.5 -> 56.25
B9: 200 | C9: =B9*C10 -> 11250
B10: 1 | C10: 56.25
B13: donc il vaut mieux employer un nouveau empolyé

Sheet Ajouts
A1: Type | B1: Période_achat | C1: Quantité
A2: MX | B2: -10 | C2: 10
A3: MX | B3: 3 | C3: 1
A4: MY | B4: 2 | C4: 1
A5: MY | B5: 4 | C5: 1
A6: MX | B6: 5 | C6: 1

Sheet Totaux_Par_Type
A1: Type | B1: P1 | C1: P2 | D1: P3 | E1: P4 | F1: P5 | G1: P6 | H1: P7 | I1: P8 | J1: P9 | K1: P10 | L1: P11 | M1: P12
A2: TOTAL GÉNÉRAL | B2: =SUM(_xlfn.ANCHORARRAY(B3)) -> 236250 | C2: =SUM(_xlfn.ANCHORARRAY(C3)) -> 247500 | D2: =SUM(_xlfn.ANCHORARRAY(D3)) -> 271875 | E2: =SUM(_xlfn.ANCHORARRAY(E3)) -> 278625 | F2: =SUM(_xlfn.ANCHORARRAY(F3)) -> 298500 | G2: =SUM(_xlfn.ANCHORARRAY(G3)) -> 263250 | H2: =SUM(_xlfn.ANCHORARRAY(H3)) -> 228000 | I2: =SUM(_xlfn.ANCHORARRAY(I3)) -> 192750 | ... M2: =SUM(_xlfn.ANCHORARRAY(M3)) -> 104250
A3: {=Param_Machines!A2:INDEX(Param_Machines!A:A,COUNTA(Param_Machines!A:A))} -> MX | B3: {=_xlfn.MAP(_xlfn.ANCHORARRAY($A3),_xlfn.LAMBDA(_xlpm.t,SUMIF(Capacité_Période!$A:$A,_xlpm.t&"*",Capacité_Période!B:B)))} -> 236250 | C3: {=_xlfn.MAP(_xlfn.ANCHORARRAY($A3),_xlfn.LAMBDA(_xlpm.t,SUMIF(Capacité_Période!$A:$A,_xlpm.t&"*",Capacité_Période!C:C)))} -> 210000 | D3: {=_xlfn.MAP(_xlfn.ANCHORARRAY($A3),_xlfn.LAMBDA(_xlpm.t,SUMIF(Capacité_Période!$A:$A,_xlpm.t&"*",Capacité_Période!D:D)))} -> 236250 | E3: {=_xlfn.MAP(_xlfn.ANCHORARRAY($A3),_xlfn.LAMBDA(_xlpm.t,SUMIF(Capacité_Période!$A:$A,_xlpm.t&"*",Capacité_Période!E:E)))} -> 207375 | F3: {=_xlfn.MAP(_xlfn.ANCHORARRAY($A3),_xlfn.LAMBDA(_xlpm.t,SUMIF(Capacité_Période!$A:$A,_xlpm.t&"*",Capacité_Période!F:F)))} -> 231000 | G3: {=_xlfn.MAP(_xlfn.ANCHORARRAY($A3),_xlfn.LAMBDA(_xlpm.t,SUMIF(Capacité_Période!$A:$A,_xlpm.t&"*",Capacité_Période!G:G)))} -> 199500 | H3: {=_xlfn.MAP(_xlfn.ANCHORARRAY($A3),_xlfn.LAMBDA(_xlpm.t,SUMIF(Capacité_Période!$A:$A,_xlpm.t&"*",Capacité_Période!H:H)))} -> 168000 | I3: {=_xlfn.MAP(_xlfn.ANCHORARRAY($A3),_xlfn.LAMBDA(_xlpm.t,SUMIF(Capacité_Période!$A:$A,_xlpm.t&"*",Capacité_Période!I:I)))} -> 136500 | J3: {=_xlfn.MAP(_xlfn.ANCHORARRAY($A3),_xlfn.LAMBDA(_xlpm.t,SUMIF(Capacité_Période!$A:$A,_xlpm.t&"*",Capacité_Période!J:J)))} -> 105000 | K3: {=_xlfn.MAP(_xlfn.ANCHORARRAY($A3),_xlfn.LAMBDA(_xlpm.t,SUMIF(Capacité_Période!$A:$A,_xlpm.t&"*",Capacité_Période!K:K)))} -> 73500 | L3: {=_xlfn.MAP(_xlfn.ANCHORARRAY($A3),_xlfn.LAMBDA(_xlpm.t,SUMIF(Capacité_Période!$A:$A,_xlpm.t&"*",Capacité_Période!L:L)))} -> 68250 | M3: {=_xlfn.MAP(_xlfn.ANCHORARRAY($A3),_xlfn.LAMBDA(_xlpm.t,SUMIF(Capacité_Période!$A:$A,_xlpm.t&"*",Capacité_Période!M:M)))} -> 63000
A4: MY | B4: 0 | C4: 37500 | D4: 35625 | E4: 71250 | F4: 67500 | G4: 63750 | H4: 60000 | I4: 56250 | J4: 52500 | K4: 48750 | L4: 45000 | M4: 41250

Sheet Param_Machines
A1: Type | B1: Capacité_initiale | C1: Usure_trimestrielle | D1: Surcapacité_max
A2: MX | B2: 35000 | C2: 5 | D2: 150
A3: MY | B3: 25000 | C3: 5 | D3: 150

Sheet Parc_Machines
A1: ID_Machine | B1: Type | C1: Période_achat
A2: {=_xlfn.LET(_xlpm.data, _xlfn._xlws.FILTER(Ajouts!A2:C100, Ajouts!A2:A100<>""),_xlpm.sorted, _xlfn._xlws.SORT(_xlpm.data, 2, 1),_xlpm.types, INDEX(_xlpm.sorted,,1),_xlpm.per, INDEX(_xlpm.sorted,,2),_xlpm.qte, INDEX(_xlpm.sorted,,3),_xlpm.nRows, ROWS(_xlpm.sorted),_xlpm.decalages, _xlfn.MAP(_xlfn.SEQUENCE(_xlpm.nRows), _xlfn.LAMBDA(_xlpm.r, IF(_xlpm.r=1, 0, SUMPRODUCT( (INDEX(_xlpm.types, _xlfn.SEQUENCE(_xlpm.r-1)) = INDEX(_xlpm.types, _xlpm.r)) * INDEX(_xlpm.qte, _xlfn.SEQUENCE(_xlpm.r-1)) ) ))),_xlpm.total, SUM(_xlpm.qte),_xlpm.seq, _xlfn.SEQUENCE(_xlpm.total),_xlpm.cumul, _xlfn.SCAN(0, _xlpm.qte, _xlfn.LAMBDA(_xlpm.a,_xlpm.b, _xlpm.a+_xlpm.b)),_xlpm.bornes, _xlfn.VSTACK(0, _xlpm.cumul),_xlpm.idx, MATCH(_xlpm.seq-0.5, _xlpm.bornes, 1),_xlpm.theType, INDEX(_xlpm.types, _xlpm.idx),_xlpm.thePer, INDEX(_xlpm.per, _xlpm.idx),_xlpm.theDecal, INDEX(_xlpm.decalages, _xlpm.idx),_xlpm.localNum, _xlpm.seq - INDEX(_xlpm.bornes, _xlpm.idx),_xlpm.globalNum, _xlpm.localNum + _xlpm.theDecal,_xlpm.theID, _xlpm.theType & "_" & TEXT(_xlpm.globalNum, "00"),_xlfn.HSTACK(_xlpm.theID, _xlpm.theType, _xlpm.thePer))} -> MX_01 | B2: MX | C2: -10
A3: MX_02 | B3: MX | C3: -10
A4: MX_03 | B4: MX | C4: -10
A5: MX_04 | B5: MX | C5: -10
A6: MX_05 | B6: MX | C6: -10
A7: MX_06 | B7: MX | C7: -10
A8: MX_07 | B8: MX | C8: -10
A9: MX_08 | B9: MX | C9: -10
A10: MX_09 | B10: MX | C10: -10
A11: MX_10 | B11: MX | C11: -10
A12: MY_01 | B12: MY | C12: 2
A13: MX_11 | B13: MX | C13: 3
A14: MY_02 | B14: MY | C14: 4
A15: MX_12 | B15: MX | C15: 5

Sheet Capacité_Période
A1: ID_Machine | B1: P1 | C1: P2 | D1: P3 | E1: P4 | F1: P5 | G1: P6 | H1: P7 | I1: P8 | J1: P9 | K1: P10 | L1: P11 | M1: P12
A2: {=INDEX(_xlfn.ANCHORARRAY(Parc_Machines!A2),,1)} -> MX_01 | B2: {=_xlfn.LET( _xlpm.types,Parc_Machines!$B$2:INDEX(Parc_Machines!$B:$B,COUNTA(Parc_Machines!$A:$A)), _xlpm.achats,Parc_Machines!$C$2:INDEX(Parc_Machines!$C:$C,COUNTA(Parc_Machines!$A:$A)), _xlpm.periode,VALUE(SUBSTITUTE(B$1,"P","")), _xlfn.MAP(_xlfn.SEQUENCE(ROWS(_xlpm.types)),_xlfn.LAMBDA(_xlpm.r, _xlfn.LET( _xlpm.type,INDEX(_xlpm.types,_xlpm.r), _xlpm.achat,INDEX(_xlpm.achats,_xlpm.r), _xlpm.cap0,_xlfn.XLOOKUP(_xlpm.type,Param_Machines!$A$2:$A$11,Param_Machines!$B$2:$B$11,0), _xlpm.usure,_xlfn.XLOOKUP(_xlpm.type,Param_Machines!$A$2:$A$11,Param_Machines!$C$2:$C$11,0)/100, _xlpm.surcapPct,_xlfn.XLOOKUP(_xlpm.type,Param_Machines!$A$2:$A$11,Param_Machines!$D$2:$D$11,100)/100, _xlpm.age,_xlpm.periode-_xlpm.achat, _xlpm.capRestante,_xlpm.cap0-_xlpm.cap0*_xlpm.usure*_xlpm.age, _xlpm.capMax,_xlpm.capRestante*_xlpm.surcapPct, IF(_xlpm.type="","",IF(_xlpm.age<0,0,MIN(MAX(0,_xlpm.capMax)))) ) )) )} -> 23625 | C2: {=_xlfn.LET( _xlpm.types,Parc_Machines!$B$2:INDEX(Parc_Machines!$B:$B,COUNTA(Parc_Machines!$A:$A)), _xlpm.achats,Parc_Machines!$C$2:INDEX(Parc_Machines!$C:$C,COUNTA(Parc_Machines!$A:$A)), _xlpm.periode,VALUE(SUBSTITUTE(C$1,"P","")), _xlfn.MAP(_xlfn.SEQUENCE(ROWS(_xlpm.types)),_xlfn.LAMBDA(_xlpm.r, _xlfn.LET( _xlpm.type,INDEX(_xlpm.types,_xlpm.r), _xlpm.achat,INDEX(_xlpm.achats,_xlpm.r), _xlpm.cap0,_xlfn.XLOOKUP(_xlpm.type,Param_Machines!$A$2:$A$11,Param_Machines!$B$2:$B$11,0), _xlpm.usure,_xlfn.XLOOKUP(_xlpm.type,Param_Machines!$A$2:$A$11,Param_Machines!$C$2:$C$11,0)/100, _xlpm.surcapPct,_xlfn.XLOOKUP(_xlpm.type,Param_Machines!$A$2:$A$11,Param_Machines!$D$2:$D$11,100)/100, _xlpm.age,_xlpm.periode-_xlpm.achat, _xlpm.capRestante,_xlpm.cap0-_xlpm.cap0*_xlpm.usure*_xlpm.age, _xlpm.capMax,_xlpm.capRestante*_xlpm.surcapPct, IF(_xlpm.type="","",IF(_xlpm.age<0,0,MIN(MAX(0,_xlpm.capMax)))) ) )) )} -> 21000 | D2: {=_xlfn.LET( _xlpm.types,Parc_Machines!$B$2:INDEX(Parc_Machines!$B:$B,COUNTA(Parc_Machines!$A:$A)), _xlpm.achats,Parc_Machines!$C$2:INDEX(Parc_Machines!$C:$C,COUNTA(Parc_Machines!$A:$A)), _xlpm.periode,VALUE(SUBSTITUTE(D$1,"P","")), _xlfn.MAP(_xlfn.SEQUENCE(ROWS(_xlpm.types)),_xlfn.LAMBDA(_xlpm.r, _xlfn.LET( _xlpm.type,INDEX(_xlpm.types,_xlpm.r), _xlpm.achat,INDEX(_xlpm.achats,_xlpm.r), _xlpm.cap0,_xlfn.XLOOKUP(_xlpm.type,Param_Machines!$A$2:$A$11,Param_Machines!$B$2:$B$11,0), _xlpm.usure,_xlfn.XLOOKUP(_xlpm.type,Param_Machines!$A$2:$A$11,Param_Machines!$C$2:$C$11,0)/100, _xlpm.surcapPct,_xlfn.XLOOKUP(_xlpm.type,Param_Machines!$A$2:$A$11,Param_Machines!$D$2:$D$11,100)/100, _xlpm.age,_xlpm.periode-_xlpm.achat, _xlpm.capRestante,_xlpm.cap0-_xlpm.cap0*_xlpm.usure*_xlpm.age, _xlpm.capMax,_xlpm.capRestante*_xlpm.surcapPct, IF(_xlpm.type="","",IF(_xlpm.age<0,0,MIN(MAX(0,_xlpm.capMax)))) ) )) )} -> 18375 | E2: {=_xlfn.LET( _xlpm.types,Parc_Machines!$B$2:INDEX(Parc_Machines!$B:$B,COUNTA(Parc_Machines!$A:$A)), _xlpm.achats,Parc_Machines!$C$2:INDEX(Parc_Machines!$C:$C,COUNTA(Parc_Machines!$A:$A)), _xlpm.periode,VALUE(SUBSTITUTE(E$1,"P","")), _xlfn.MAP(_xlfn.SEQUENCE(ROWS(_xlpm.types)),_xlfn.LAMBDA(_xlpm.r, _xlfn.LET( _xlpm.type,INDEX(_xlpm.types,_xlpm.r), _xlpm.achat,INDEX(_xlpm.achats,_xlpm.r), _xlpm.cap0,_xlfn.XLOOKUP(_xlpm.type,Param_Machines!$A$2:$A$11,Param_Machines!$B$2:$B$11,0), _xlpm.usure,_xlfn.XLOOKUP(_xlpm.type,Param_Machines!$A$2:$A$11,Param_Machines!$C$2:$C$11,0)/100, _xlpm.surcapPct,_xlfn.XLOOKUP(_xlpm.type,Param_Machines!$A$2:$A$11,Param_Machines!$D$2:$D$11,100)/100, _xlpm.age,_xlpm.periode-_xlpm.achat, _xlpm.capRestante,_xlpm.cap0-_xlpm.cap0*_xlpm.usure*_xlpm.age, _xlpm.capMax,_xlpm.capRestante*_xlpm.surcapPct, IF(_xlpm.type="","",IF(_xlpm.age<0,0,MIN(MAX(0,_xlpm.capMax)))) ) )) )} -> 15750 | F2: {=_xlfn.LET( _xlpm.types,Parc_Machines!$B$2:INDEX(Parc_Machines!$B:$B,COUNTA(Parc_Machines!$A:$A)), _xlpm.achats,Parc_Machines!$C$2:INDEX(Parc_Machines!$C:$C,COUNTA(Parc_Machines!$A:$A)), _xlpm.periode,VALUE(SUBSTITUTE(F$1,"P","")), _xlfn.MAP(_xlfn.SEQUENCE(ROWS(_xlpm.types)),_xlfn.LAMBDA(_xlpm.r, _xlfn.LET( _xlpm.type,INDEX(_xlpm.types,_xlpm.r), _xlpm.achat,INDEX(_xlpm.achats,_xlpm.r), _xlpm.cap0,_xlfn.XLOOKUP(_xlpm.type,Param_Machines!$A$2:$A$11,Param_Machines!$B$2:$B$11,0), _xlpm.usure,_xlfn.XLOOKUP(_xlpm.type,Param_Machines!$A$2:$A$11,Param_Machines!$C$2:$C$11,0)/100, _xlpm.surcapPct,_xlfn.XLOOKUP(_xlpm.type,Param_Machines!$A$2:$A$11,Param_Machines!$D$2:$D$11,100)/100, _xlpm.age,_xlpm.periode-_xlpm.achat, _xlpm.capRestante,_xlpm.cap0-_xlpm.cap0*_xlpm.usure*_xlpm.age, _xlpm.capMax,_xlpm.capRestante*_xlpm.surcapPct, IF(_xlpm.type="","",IF(_xlpm.age<0,0,MIN(MAX(0,_xlpm.capMax)))) ) )) )} -> 13125 | G2: {=_xlfn.LET( _xlpm.types,Parc_Machines!$B$2:INDEX(Parc_Machines!$B:$B,COUNTA(Parc_Machines!$A:$A)), _xlpm.achats,Parc_Machines!$C$2:INDEX(Parc_Machines!$C:$C,COUNTA(Parc_Machines!$A:$A)), _xlpm.periode,VALUE(SUBSTITUTE(G$1,"P","")), _xlfn.MAP(_xlfn.SEQUENCE(ROWS(_xlpm.types)),_xlfn.LAMBDA(_xlpm.r, _xlfn.LET( _xlpm.type,INDEX(_xlpm.types,_xlpm.r), _xlpm.achat,INDEX(_xlpm.achats,_xlpm.r), _xlpm.cap0,_xlfn.XLOOKUP(_xlpm.type,Param_Machines!$A$2:$A$11,Param_Machines!$B$2:$B$11,0), _xlpm.usure,_xlfn.XLOOKUP(_xlpm.type,Param_Machines!$A$2:$A$11,Param_Machines!$C$2:$C$11,0)/100, _xlpm.surcapPct,_xlfn.XLOOKUP(_xlpm.type,Param_Machines!$A$2:$A$11,Param_Machines!$D$2:$D$11,100)/100, _xlpm.age,_xlpm.periode-_xlpm.achat, _xlpm.capRestante,_xlpm.cap0-_xlpm.cap0*_xlpm.usure*_xlpm.age, _xlpm.capMax,_xlpm.capRestante*_xlpm.surcapPct, IF(_xlpm.type="","",IF(_xlpm.age<0,0,MIN(MAX(0,_xlpm.capMax)))) ) )) )} -> 10500 | H2: {=_xlfn.LET( _xlpm.types,Parc_Machines!$B$2:INDEX(Parc_Machines!$B:$B,COUNTA(Parc_Machines!$A:$A)), _xlpm.achats,Parc_Machines!$C$2:INDEX(Parc_Machines!$C:$C,COUNTA(Parc_Machines!$A:$A)), _xlpm.periode,VALUE(SUBSTITUTE(H$1,"P","")), _xlfn.MAP(_xlfn.SEQUENCE(ROWS(_xlpm.types)),_xlfn.LAMBDA(_xlpm.r, _xlfn.LET( _xlpm.type,INDEX(_xlpm.types,_xlpm.r), _xlpm.achat,INDEX(_xlpm.achats,_xlpm.r), _xlpm.cap0,_xlfn.XLOOKUP(_xlpm.type,Param_Machines!$A$2:$A$11,Param_Machines!$B$2:$B$11,0), _xlpm.usure,_xlfn.XLOOKUP(_xlpm.type,Param_Machines!$A$2:$A$11,Param_Machines!$C$2:$C$11,0)/100, _xlpm.surcapPct,_xlfn.XLOOKUP(_xlpm.type,Param_Machines!$A$2:$A$11,Param_Machines!$D$2:$D$11,100)/100, _xlpm.age,_xlpm.periode-_xlpm.achat, _xlpm.capRestante,_xlpm.cap0-_xlpm.cap0*_xlpm.usure*_xlpm.age, _xlpm.capMax,_xlpm.capRestante*_xlpm.surcapPct, IF(_xlpm.type="","",IF(_xlpm.age<0,0,MIN(MAX(0,_xlpm.capMax)))) ) )) )} -> 7875 | I2: {=_xlfn.LET( _xlpm.types,Parc_Machines!$B$2:INDEX(Parc_Machines!$B:$B,COUNTA(Parc_Machines!$A:$A)), _xlpm.achats,Parc_Machines!$C$2:INDEX(Parc_Machines!$C:$C,COUNTA(Parc_Machines!$A:$A)), _xlpm.periode,VALUE(SUBSTITUTE(I$1,"P","")), _xlfn.MAP(_xlfn.SEQUENCE(ROWS(_xlpm.types)),_xlfn.LAMBDA(_xlpm.r, _xlfn.LET( _xlpm.type,INDEX(_xlpm.types,_xlpm.r), _xlpm.achat,INDEX(_xlpm.achats,_xlpm.r), _xlpm.cap0,_xlfn.XLOOKUP(_xlpm.type,Param_Machines!$A$2:$A$11,Param_Machines!$B$2:$B$11,0), _xlpm.usure,_xlfn.XLOOKUP(_xlpm.type,Param_Machines!$A$2:$A$11,Param_Machines!$C$2:$C$11,0)/100, _xlpm.surcapPct,_xlfn.XLOOKUP(_xlpm.type,Param_Machines!$A$2:$A$11,Param_Machines!$D$2:$D$11,100)/100, _xlpm.age,_xlpm.periode-_xlpm.achat, _xlpm.capRestante,_xlpm.cap0-_xlpm.cap0*_xlpm.usure*_xlpm.age, _xlpm.capMax,_xlpm.capRestante*_xlpm.surcapPct, IF(_xlpm.type="","",IF(_xlpm.age<0,0,MIN(MAX(0,_xlpm.capMax)))) ) )) )} -> 5250 | ... M2: {=_xlfn.LET( _xlpm.types,Parc_Machines!$B$2:INDEX(Parc_Machines!$B:$B,COUNTA(Parc_Machines!$A:$A)), _xlpm.achats,Parc_Machines!$C$2:INDEX(Parc_Machines!$C:$C,COUNTA(Parc_Machines!$A:$A)), _xlpm.periode,VALUE(SUBSTITUTE(M$1,"P","")), _xlfn.MAP(_xlfn.SEQUENCE(ROWS(_xlpm.types)),_xlfn.LAMBDA(_xlpm.r, _xlfn.LET( _xlpm.type,INDEX(_xlpm.types,_xlpm.r), _xlpm.achat,INDEX(_xlpm.achats,_xlpm.r), _xlpm.cap0,_xlfn.XLOOKUP(_xlpm.type,Param_Machines!$A$2:$A$11,Param_Machines!$B$2:$B$11,0), _xlpm.usure,_xlfn.XLOOKUP(_xlpm.type,Param_Machines!$A$2:$A$11,Param_Machines!$C$2:$C$11,0)/100, _xlpm.surcapPct,_xlfn.XLOOKUP(_xlpm.type,Param_Machines!$A$2:$A$11,Param_Machines!$D$2:$D$11,100)/100, _xlpm.age,_xlpm.periode-_xlpm.achat, _xlpm.capRestante,_xlpm.cap0-_xlpm.cap0*_xlpm.usure*_xlpm.age, _xlpm.capMax,_xlpm.capRestante*_xlpm.surcapPct, IF(_xlpm.type="","",IF(_xlpm.age<0,0,MIN(MAX(0,_xlpm.capMax)))) ) )) )} -> 0
A3: MX_02 | B3: 23625 | C3: 21000 | D3: 18375 | E3: 15750 | F3: 13125 | G3: 10500 | H3: 7875 | I3: 5250 | J3: 2625 | K3: 0 | L3: 0 | M3: 0
A4: MX_03 | B4: 23625 | C4: 21000 | D4: 18375 | E4: 15750 | F4: 13125 | G4: 10500 | H4: 7875 | I4: 5250 | J4: 2625 | K4: 0 | L4: 0 | M4: 0
A5: MX_04 | B5: 23625 | C5: 21000 | D5: 18375 | E5: 15750 | F5: 13125 | G5: 10500 | H5: 7875 | I5: 5250 | J5: 2625 | K5: 0 | L5: 0 | M5: 0
A6: MX_05 | B6: 23625 | C6: 21000 | D6: 18375 | E6: 15750 | F6: 13125 | G6: 10500 | H6: 7875 | I6: 5250 | J6: 2625 | K6: 0 | L6: 0 | M6: 0
A7: MX_06 | B7: 23625 | C7: 21000 | D7: 18375 | E7: 15750 | F7: 13125 | G7: 10500 | H7: 7875 | I7: 5250 | J7: 2625 | K7: 0 | L7: 0 | M7: 0
A8: MX_07 | B8: 23625 | C8: 21000 | D8: 18375 | E8: 15750 | F8: 13125 | G8: 10500 | H8: 7875 | I8: 5250 | J8: 2625 | K8: 0 | L8: 0 | M8: 0
A9: MX_08 | B9: 23625 | C9: 21000 | D9: 18375 | E9: 15750 | F9: 13125 | G9: 10500 | H9: 7875 | I9: 5250 | J9: 2625 | K9: 0 | L9: 0 | M9: 0
A10: MX_09 | B10: 23625 | C10: 21000 | D10: 18375 | E10: 15750 | F10: 13125 | G10: 10500 | H10: 7875 | I10: 5250 | J10: 2625 | K10: 0 | L10: 0 | M10: 0
A11: MX_10 | B11: 23625 | C11: 21000 | D11: 18375 | E11: 15750 | F11: 13125 | G11: 10500 | H11: 7875 | I11: 5250 | J11: 2625 | K11: 0 | L11: 0 | M11: 0
A12: MY_01 | B12: 0 | C12: 37500 | D12: 35625 | E12: 33750 | F12: 31875 | G12: 30000 | H12: 28125 | I12: 26250 | J12: 24375 | K12: 22500 | L12: 20625 | M12: 18750
A13: MX_11 | B13: 0 | C13: 0 | D13: 52500 | E13: 49875 | F13: 47250 | G13: 44625 | H13: 42000 | I13: 39375 | J13: 36750 | K13: 34125 | L13: 31500 | M13: 28875
A14: MY_02 | B14: 0 | C14: 0 | D14: 0 | E14: 37500 | F14: 35625 | G14: 33750 | H14: 31875 | I14: 30000 | J14: 28125 | K14: 26250 | L14: 24375 | M14: 22500
A15: MX_12 | B15: 0 | C15: 0 | D15: 0 | E15: 0 | F15: 52500 | G15: 49875 | H15: 47250 | I15: 44625 | J15: 42000 | K15: 39375 | L15: 36750 | M15: 34125

Sheet P2
A1: ENCAISSEMENT | D1: DECAISSEMENT
A2: Trésorerie | B2: 6527 | D2: Paiement Matières 1ères | E2: 10626
A3: Clients T-1 | B3: 37820 | D3: Fournisseurs Machines | E3: 2000
A4: Effets escomptés | B4: 0 | D4: Emprunts + Découvert | E4: 0
A5: Emprunts | B5: 0 | D5: Frais de Personnel | E5: 12813
A6: Découvert | B6: 0 | D6: Coûts Variables P° + R&D | E6: 5200
A7: Ventes Machines MX | B7: 0 | D7: Frais de Vente + Publicité | E7: 1500
A8: Retour d’Impôt | B8: 0 | D8: Frais de Gestion | E8: 2000
A9: Ventes BdC | B9: 0 | D9: Frais Financiers | E9: 0
A10: Produits Financiers | B10: 160 | D10: Autres Décaissements | E10: 4000
A11: Autres encaissements | B11: 0 | D11: Impôts | E11: 772
A12: Total | B12: =SUM(B2:B11) -> 44507 | D12: Achats BdC | E12: 0
D13: Total | E13: =SUM(E2:E12) -> 38911
A14: TOTAL
A15: =B12-E13 -> 5596
A25: Trésorerie | B25: Encaissements | C25: total | D25: Décaissements
A26: 15134 | B26: 27559 | C26: =A26+B26 -> 42693 | E26: Paiement Fournisseurs | F26: Frais de Personnel | G26: machine | H26: Coûts Variables de Production | I26: Publicité | J26: R&D | K26: Frais de Gestion & Vente | L26: Études de Marché | M26: Impôts (de P0) & Frais divers | N26: Total
E27: 10625 | F27: 11250 | G27: 2000 | H27: 3500 | I27: 800 | J27: 100 | K27: 2500 | L27: 10 | M27: 23 | N27: =SUM(E27:M27) -> 30808
C28: c'est que pour ski elite
A30: Trésorerie Final
A31: =C26-N27 -> 11885

Sheet P1
A1: Trésorerie | B1: Encaissements | C1: total | D1: Décaissements
A2: 15134 | B2: 27559 | C2: =A2+B2 -> 42693 | E2: Paiement Fournisseurs | F2: Frais de Personnel | H2: Coûts Variables de Production | I2: Publicité | J2: R&D | K2: Frais de Gestion & Vente | L2: Études de Marché | M2: Impôts (de P0) & Frais divers | N2: Total
E3: 16125 | F3: 11250 | H3: 3500 | I3: 800 | J3: 100 | K3: 2500 | L3: 10 | M3: 23 | N3: =SUM(E3:M3) -> 34308
C4: c'est que pour ski elite
A6: Trésorerie Final
A7: =C2-N3 -> 8385

Sheet Trésorerie P1
A1: ENCAISSEMENT | D1: DECAISSEMENT
A2: Clients T-1 | B2: 27559 | D2: Paiement Matières 1ères | E2: 16125
A3: Effets escomptés | B3: 0 | D3: Fournisseurs Machines | E3: 0
A4: Emprunts | B4: 0 | D4: Emprunts + Découvert | E4: 0
A5: Découvert | B5: 0 | D5: Frais de Personnel | E5: 11250
A6: Ventes Machines MX | B6: 0 | D6: Coûts Variables P° + R&D | E6: 5100
A7: Retour d’Impôt | B7: 0 | D7: Frais de Vente + Publicité | E7: 1200
A8: Ventes BdC | B8: 0 | D8: Frais de Gestion | E8: 2000
A9: Produits Financiers | B9: 0 | D9: Frais Financiers | E9: 0
A10: Autres encaissements | B10: 0 | D10: Autres Décaissements | E10: 0
A11: Total | B11: =SUM(B2:B10) -> 27559 | D11: Impôts | E11: 772
D12: Achats BdC | E12: 6400
D13: Total | E13: =SUM(E2:E12) -> 42847

Sheet Trésorie previsionnelle P3
A1: ENCAISSEMENT | D1: DECAISSEMENT
A2: Clients T-1 | B2: 57189 | D2: Paiement Matières 1ères | E2: 17625
A3: Effets escomptés | B3: 0 | D3: Fournisseurs Machines | E3: 2500
A4: Emprunts | B4: 0 | D4: Emprunts + Découvert | E4: 0
A5: Découvert | B5: 0 | D5: Frais de Personnel | E5: 13894 | F5: pas la meme chose | G5: c'est 13 275 | I5: -> | K5: Main d'oeuvre de production 11 894
A6: Ventes Machines MX | B6: 0 | D6: Coûts Variables P° + R&D | E6: 7653 | F6: 7 027 | K6: Salaires Cadres 375
A7: Retour d’Impôt | B7: 0 | D7: Frais de Vente + Publicité | E7: 1500 | K7: Salaires Vendeurs + Embauche/Licenciement 625
A8: Ventes BdC | B8: 6400 | D8: Frais de Gestion | E8: 2000 | K8: Salaires Administratifs 1 000
A9: Produits Financiers | B9: 128 | D9: Frais Financiers | E9: 0
A10: Autres encaissements | B10: 0 | D10: Autres Décaissements | E10: 4020 | F10: 2 020
A11: Total | B11: =SUM(B2:B10) -> 63717 | D11: Impôts | E11: 364 | F11: 2 012
D12: Achats BdC | E12: 4400 | F12: 13 200
A13: Tresorerie nette P3 | D13: Total | E13: =SUM(E2:E12) -> 53956
A14: =B11-E13+127 -> 9888

Sheet Trésorerie P4
A1: ENCAISSEMENT | B1: Créances clients | D1: DECAISSEMENT
A2: Clients T-1 | B2: 43450 | D2: Paiement Matières 1ères | E2: 22238 | F2: Dettes Fournisseurs M.P. bilan
A3: Effets escomptés | B3: 0 | D3: Fournisseurs Machines | E3: 2000 | F3: P
A4: Emprunts | B4: 0 | D4: Emprunts + Découvert | E4: 0 | F4: main d'oeuvre prod | G4: Salaires Vendeurs + Embauche/Licenciement | H4: Salaires Cadres | I4: Salaires Administratifs | J4: ouvrier en plus
A5: Découvert | B5: 0 | D5: Frais de Personnel | E5: =SUM(F5:J5) -> 13770 | F5: 11275 | G5: 625 | H5: 375 | I5: 1000 | J5: =(K18*750+K18*7500)/1000 -> 495
A6: Ventes Machines MX | B6: 0 | D6: Coûts Variables P° + R&D +Eco | E6: =SUM(F6:H6) -> 6920 | F6: =I18*J18 -> 4720 | G6: 200 | H6: 2000
A7: Retour d’Impôt | B7: 0 | D7: Frais de Vente + Publicité | E7: =SUM(F7:G7) -> 1500 | F7: 500 | G7: 1000 | H7: P
A8: Ventes BdC | B8: 13200 | D8: Frais de Gestion | E8: 2000 | F8: meme
A9: Produits Financiers | B9: =0.8*0.025*B8 -> 264 | D9: Frais Financiers | E9: 0 | F9: Dépenses QVT | G9: Comptabilité analytique | H9: Coûts Certification | I9: Etude Marché / raquette (O/N)
A10: Autres encaissements | B10: 0 | D10: Autres Décaissements | E10: =SUM(F10:I10) -> 3530 | F10: 2000 | G10: 20 | H10: 1500 | I10: 10
A11: Total | B11: =SUM(B2:B10) -> 56914 | D11: Impôts | E11: =F11*0.33 -> 2012.01 | F11: 6097 | G11: RESULTAT AVANT IMPOT 2
D12: Achats BdC | E12: 2800 | F12: 13355 | G12: =ROUNDDOWN(F12,-2) -> 13300
A13: Tresorerie nette | D13: Total | E13: =SUM(E2:E12) -> 56770.01 | F13: trésorerie
A14: =B11-E13 -> 143.99
F17: Dotation aux Amortissements | I17: nb de production | J17: Coût Variable Unitaire | K17: ouvrier
F18: 1 475 | I18: 236 | J18: 20 | K18: 60

Sheet Trésorerie P5
A1: ENCAISSEMENT | B1: Créances clients | D1: DECAISSEMENT
A2: Clients T-1 | B2: 37198 | D2: Paiement Matières 1ères | E2: 7451 | F2: Dettes Fournisseurs M.P. bilan
A3: Effets escomptés | B3: 800 | D3: Fournisseurs Machines | E3: 2500 | F3: P
A4: Emprunts | B4: 0 | D4: Emprunts + Découvert | E4: 0 | F4: main d'oeuvre prod | G4: Salaires Vendeurs + Embauche/Licenciement | H4: Salaires Cadres | I4: Salaires Administratifs
A5: Découvert | B5: 0 | D5: Frais de Personnel | E5: =SUM(F5:J5) -> 14726 | F5: 12726 | G5: 625 | H5: 375 | I5: 1000 | J5: moe
A6: Ventes Machines MX | B6: 0 | D6: Coûts Variables P° + R&D +Eco | E6: =SUM(F6:H6) -> 7500 | F6: =I18*J18 -> 5300 | G6: 200 | H6: 2000
A7: Retour d’Impôt | B7: 0 | D7: Frais de Vente + Publicité | E7: =SUM(F7:G7) -> 1700 | F7: 500 | G7: 1200 | H7: P
A8: Ventes BdC | B8: 2600 | D8: Frais de Gestion | E8: 2000 | F8: meme
A9: Produits Financiers | B9: =0.8*0.025*B8 -> 52 | D9: Frais Financiers | E9: 0 | F9: Dépenses QVT | G9: Comptabilité analytique | H9: Coûts Certification | I9: Etude Marché / raquette (O/N)
A10: Autres encaissements | B10: 0 | D10: Autres Décaissements | E10: =SUM(F10:I10) -> 3530 | F10: 2000 | G10: 20 | H10: 1500 | I10: 10
A11: Total | B11: =SUM(B2:B10) -> 40650 | D11: Impôts | E11: =F11*0.33 -> 837.21 | F11: 2537 | G11: RESULTAT AVANT IMPOT 2
D12: Achats BdC | E12: 400
A13: Tresorerie nette | D13: Total | E13: =SUM(E2:E12) -> 40644.21 | F13: trésorerie
A14: =B11-E13 -> 5.79
D17: =42000*0.02 -> 840 | I17: nb de production | J17: Coût Variable Unitaire
I18: 265 | J18: 20

Sheet Trésorerie P6
A1: ENCAISSEMENT | B1: Créances clients | D1: DECAISSEMENT
A2: Clients T-1 | B2: 38154 | D2: Paiement Matières 1ères | E2: 23344 | F2: Dettes Fournisseurs M.P. bilan
A3: Effets escomptés | D3: Fournisseurs Machines | E3: 0 | F3: P
A4: Emprunts | B4: 0 | D4: Emprunts + Découvert | E4: 0 | F4: main d'oeuvre prod | G4: Salaires Vendeurs + Embauche/Licenciement | H4: Salaires Cadres | I4: Salaires Administratifs
A5: Découvert | B5: 0 | D5: Frais de Personnel | E5: =SUM(F5:J5) -> 14681 | F5: 12681 | G5: 625 | H5: 375 | I5: 1000 | J5: moe
A6: Ventes Machines MX | B6: 0 | D6: Coûts Variables P° + R&D +Eco | E6: =SUM(F6:H6) -> 7200 | F6: =I18*J18 -> 5000 | G6: 200 | H6: 2000
A7: Retour d’Impôt | B7: 0 | D7: Frais de Vente + Publicité | E7: =SUM(F7:G7) -> 2700 | F7: 500 | G7: 2200 | H7: P
A8: Ventes BdC | B8: 2400 | D8: Frais de Gestion | E8: 2000 | F8: meme
A9: Produits Financiers | B9: =0.8*K18*B8 -> 115.2 | D9: Frais Financiers | E9: 0 | F9: Dépenses QVT | G9: Comptabilité analytique | H9: Coûts Certification
A10: Autres encaissements | B10: 0 | D10: Autres Décaissements | E10: =SUM(F10:I10) -> 3520 | F10: 2000 | G10: 20 | H10: 1500
A11: Total | B11: =SUM(B2:B10) -> 40669.2 | D11: Impôts | E11: =F11*0.33 -> 26009.61 | F11: =L18-G11 -> 78817 | H11: RESULTAT AVANT IMPOT
D12: Achats BdC | E12: 200
A13: Tresorerie nette P3 | D13: Total | E13: =SUM(E2:E12) -> 79654.61 | F13: trésorerie
A14: =B11-E13 -> -38985.41
D15: =70000-E13 -> -9654.61
E16: =SUM(E5:E15) -> 135965.22
G17: =700+900+600 -> 2200 | I17: nb de production | J17: Coût Variable Unitaire | K17: Taux_Emprunt_CT de la Période | L17: chiffre d'aiffaire prévision
I18: 250 | J18: 20 | K18: 0.06 | L18: 78817
D22: COUT total

Sheet Trésorerie P7
A1: ENCAISSEMENT | B1: Créances clients | D1: DECAISSEMENT
A2: Clients T-1 | B2: 74088 | D2: Paiement Matières 1ères | E2: 14556 | F2: Dettes Fournisseurs M.P. bilan
A3: Effets escomptés | B3: 0 | D3: Fournisseurs Machines | E3: 0 | F3: P
A4: Emprunts | B4: 0 | D4: Emprunts + Découvert | E4: 12380 | F4: main d'oeuvre prod | G4: Salaires Vendeurs + Embauche/Licenciement | H4: Salaires Cadres | I4: Salaires Administratifs
A5: Découvert | B5: 0 | D5: Frais de Personnel | E5: =SUM(F5:J5) -> 14681 | F5: 12681 | G5: 625 | H5: 375 | I5: 1000
A6: Ventes Machines MX | B6: 0 | D6: Coûts Variables P° + R&D +Eco | E6: =SUM(F6:H6) -> 7200 | F6: =I18*J18 -> 5000 | G6: 200 | H6: 2000
A7: Retour d’Impôt | B7: 0 | D7: Frais de Vente + Publicité | E7: =SUM(F7:G7) -> 2700 | F7: 500 | G7: 2200 | H7: P
A8: Ventes BdC | B8: 0 | D8: Frais de Gestion | E8: 2000 | F8: meme
A9: Produits Financiers | B9: =0.8*K18*B8 -> 0 | D9: Frais Financiers | E9: 0 | F9: Dépenses QVT | G9: Comptabilité analytique | H9: Coûts Certification
A10: Autres encaissements | B10: 0 | D10: Autres Décaissements | E10: =SUM(F10:I10) -> 3520 | F10: 2000 | G10: 20 | H10: 1500
A11: Total | B11: =SUM(B2:B10) -> 74088 | D11: Impôts | E11: =F11*0.33 -> 883.08 | F11: 2676 | G11: RESULTAT AVANT IMPOT 2
D12: Achats BdC | E12: 200
A13: Tresorerie nette P3 | D13: Total | E13: =SUM(E2:E12) -> 58120.08 | F13: trésorerie
A14: =B11-E13 -> 15967.92
E16: =SUM(E5:E15) -> 89304.16
G17: =700+900+600 -> 2200 | I17: nb de production | J17: Coût Variable Unitaire | K17: Taux_Emprunt_CT de la Période
I18: 250 | J18: 20 | K18: 0.06

Sheet Param_MP
A1: MP
A2: Fibre
A3: Résine

Sheet Param_Produits
A1: Produit
A2: Ski Elite
A3: Ski 2000
A4: Raquette

Sheet BOM_Produits
A1: Produit | B1: Fibre | C1: Résine
A2: {=Param_Produits!A2:INDEX(Param_Produits!A:A,COUNTA(Param_Produits!A:A))} -> Ski Elite | B2: 16 | C2: 4
A3: Ski 2000 | B3: 6 | C3: 14
A4: Raquette | B4: 5 | C4: 5

Sheet Prix_MP
A1: PRIX VIRGIN | B1: {="P"&_xlfn.SEQUENCE(1, PARAMETRES_GENERAUX!$B$2, PARAMETRES_GENERAUX!$B$3)} -> P1 | C1: P2 | D1: P3 | E1: P4 | F1: P5 | G1: P6 | H1: P7 | I1: P8 | J1: P9 | K1: P10 | L1: P11 | M1: P12
A2: {=_xlfn._xlws.FILTER(Param_MP!A2:A100, Param_MP!A2:A100<>"", "")} -> Fibre | B2: 6 | C2: 6 | D2: 6 | E2: 6 | F2: 6 | G2: 6 | H2: 6 | I2: 6 | J2: 6 | K2: 6 | L2: 6 | M2: 6
A3: Résine | B3: 1.25 | C3: 1.25 | D3: 1.25 | E3: 1.25 | F3: 1.25 | G3: 1.25 | H3: 1.25 | I3: 1.25 | J3: 1.25 | K3: 1.25 | L3: 1.25 | M3: 1.25
A6: PRIX RECYCLÉ | B6: {="P"&_xlfn.SEQUENCE(1, PARAMETRES_GENERAUX!$B$2, PARAMETRES_GENERAUX!$B$3)} -> P1 | C6: P2 | D6: P3 | E6: P4 | F6: P5 | G6: P6 | H6: P7 | I6: P8 | J6: P9 | K6: P10 | L6: P11 | M6: P12
A7: {=_xlfn._xlws.FILTER(Param_MP!A2:A100, Param_MP!A2:A100<>"", "")} -> Fibre | B7: 6.5 | C7: 6.5 | D7: 6.5 | E7: 6.5 | F7: 6.5 | G7: 6.5 | H7: 6.5 | I7: 6.5 | J7: 6.5 | K7: 6.5 | L7: 6.5 | M7: 6.5
A8: Résine | B8: 1.626 | C8: 1.626 | D8: 1.626 | E8: 1.626 | F8: 1.626 | G8: 1.626 | H8: 1.626 | I8: 1.626 | J8: 1.626 | K8: 1.626 | L8: 1.626 | M8: 1.626

Sheet Mix_MP
A1: % RECYCLÉ | B1: {="P"&_xlfn.SEQUENCE(1, PARAMETRES_GENERAUX!$B$2, PARAMETRES_GENERAUX!$B$3)} -> P1 | C1: P2 | D1: P3 | E1: P4 | F1: P5 | G1: P6 | H1: P7 | I1: P8 | J1: P9 | K1: P10 | L1: P11 | M1: P12
A2: {=_xlfn._xlws.FILTER(Param_MP!A2:A100, Param_MP!A2:A100<>"", "")} -> Fibre | B2: 0.1 | C2: 0.1 | D2: 0.1 | E2: 0.1 | F2: 0.1 | G2: 0.1 | H2: 0.1 | I2: 0.1 | J2: 0.1 | K2: 0.1 | L2: 0.1 | M2: 0.1
A3: Résine | B3: 0.3 | C3: 0.3 | D3: 0.3 | E3: 0.3 | F3: 0.3 | G3: 0.3 | H3: 0.3 | I3: 0.3 | J3: 0.3 | K3: 0.3 | L3: 0.3 | M3: 0.3

Sheet Plan_Production
A1: PRODUCTION (KU) | B1: {=TRANSPOSE("P"&_xlfn.SEQUENCE(PARAMETRES_GENERAUX!$B$2))} -> P1 | C1: P2 | D1: P3 | E1: P4 | F1: P5 | G1: P6 | H1: P7 | I1: P8 | J1: P9 | K1: P10 | L1: P11 | M1: P12
A2: {=_xlfn._xlws.FILTER(Param_Produits!A2:A100, Param_Produits!A2:A100<>"")} -> Ski Elite | B2: 120 | C2: 180 | D2: 150 | E2: 200 | F2: 180 | G2: 160 | H2: 140 | I2: 170 | J2: 190 | K2: 210 | L2: 200 | M2: 180
A3: Ski 2000 | B3: 79 | C3: 100 | D3: 90 | E3: 120 | F3: 110 | G3: 100 | H3: 95 | I3: 105 | J3: 115 | K3: 125 | L3: 120 | M3: 110
A4: Raquette | B4: 50 | C4: 60 | D4: 55 | E4: 70 | F4: 65 | G4: 60 | H4: 55 | I4: 65 | J4: 70 | K4: 80 | L4: 75 | M4: 70

Sheet Besoins_Quantités
A1: BESOINS (KU) | B1: {="P"&_xlfn.SEQUENCE(1, PARAMETRES_GENERAUX!$B$2, PARAMETRES_GENERAUX!$B$3)} -> P1 | C1: P2 | D1: P3 | E1: P4 | F1: P5 | G1: P6 | H1: P7 | I1: P8 | J1: P9 | K1: P10 | L1: P11 | M1: P12
A2: TOTAL | B2: =SUM(B3:INDEX(B:B, COUNTA(Param_MP!$A:$A)+1)) -> 4480 | C2: =SUM(C3:INDEX(C:C, COUNTA(Param_MP!$A:$A)+1)) -> 6200 | D2: =SUM(D3:INDEX(D:D, COUNTA(Param_MP!$A:$A)+1)) -> 5350 | E2: =SUM(E3:INDEX(E:E, COUNTA(Param_MP!$A:$A)+1)) -> 7100 | F2: =SUM(F3:INDEX(F:F, COUNTA(Param_MP!$A:$A)+1)) -> 6450 | G2: =SUM(G3:INDEX(G:G, COUNTA(Param_MP!$A:$A)+1)) -> 5800 | H2: =SUM(H3:INDEX(H:H, COUNTA(Param_MP!$A:$A)+1)) -> 5250 | I2: =SUM(I3:INDEX(I:I, COUNTA(Param_MP!$A:$A)+1)) -> 6150 | J2: =SUM(J3:INDEX(J:J, COUNTA(Param_MP!$A:$A)+1)) -> 6800 | K2: =SUM(K3:INDEX(K:K, COUNTA(Param_MP!$A:$A)+1)) -> 7500 | L2: =SUM(L3:INDEX(L:L, COUNTA(Param_MP!$A:$A)+1)) -> 7150 | M2: =SUM(M3:INDEX(M:M, COUNTA(Param_MP!$A:$A)+1)) -> 6500
A3: {=_xlfn._xlws.FILTER(Param_MP!A2:A100, Param_MP!A2:A100<>"", "")} -> Fibre | B3: {=SUMPRODUCT( (Plan_Production!$A$2:$A$10<>"") * _xlfn.XLOOKUP(Plan_Production!$A$2:$A$10, BOM_Produits!$A$2:$A$10, INDEX(BOM_Produits!$B$2:$G$10, 0, MATCH($A3, BOM_Produits!$B$1:$G$1, 0)), 0) * INDEX(Plan_Production!$B$2:$M$10, 0, VALUE(SUBSTITUTE(B$1, "P", ""))) )} -> 2644 | C3: {=SUMPRODUCT( (Plan_Production!$A$2:$A$10<>"") * _xlfn.XLOOKUP(Plan_Production!$A$2:$A$10, BOM_Produits!$A$2:$A$10, INDEX(BOM_Produits!$B$2:$G$10, 0, MATCH($A3, BOM_Produits!$B$1:$G$1, 0)), 0) * INDEX(Plan_Production!$B$2:$M$10, 0, VALUE(SUBSTITUTE(C$1, "P", ""))) )} -> 3780 | D3: {=SUMPRODUCT( (Plan_Production!$A$2:$A$10<>"") * _xlfn.XLOOKUP(Plan_Production!$A$2:$A$10, BOM_Produits!$A$2:$A$10, INDEX(BOM_Produits!$B$2:$G$10, 0, MATCH($A3, BOM_Produits!$B$1:$G$1, 0)), 0) * INDEX(Plan_Production!$B$2:$M$10, 0, VALUE(SUBSTITUTE(D$1, "P", ""))) )} -> 3215 | E3: {=SUMPRODUCT( (Plan_Production!$A$2:$A$10<>"") * _xlfn.XLOOKUP(Plan_Production!$A$2:$A$10, BOM_Produits!$A$2:$A$10, INDEX(BOM_Produits!$B$2:$G$10, 0, MATCH($A3, BOM_Produits!$B$1:$G$1, 0)), 0) * INDEX(Plan_Production!$B$2:$M$10, 0, VALUE(SUBSTITUTE(E$1, "P", ""))) )} -> 4270 | F3: {=SUMPRODUCT( (Plan_Production!$A$2:$A$10<>"") * _xlfn.XLOOKUP(Plan_Production!$A$2:$A$10, BOM_Produits!$A$2:$A$10, INDEX(BOM_Produits!$B$2:$G$10, 0, MATCH($A3, BOM_Produits!$B$1:$G$1, 0)), 0) * INDEX(Plan_Production!$B$2:$M$10, 0, VALUE(SUBSTITUTE(F$1, "P", ""))) )} -> 3865 | G3: {=SUMPRODUCT( (Plan_Production!$A$2:$A$10<>"") * _xlfn.XLOOKUP(Plan_Production!$A$2:$A$10, BOM_Produits!$A$2:$A$10, INDEX(BOM_Produits!$B$2:$G$10, 0, MATCH($A3, BOM_Produits!$B$1:$G$1, 0)), 0) * INDEX(Plan_Production!$B$2:$M$10, 0, VALUE(SUBSTITUTE(G$1, "P", ""))) )} -> 3460 | H3: {=SUMPRODUCT( (Plan_Production!$A$2:$A$10<>"") * _xlfn.XLOOKUP(Plan_Production!$A$2:$A$10, BOM_Produits!$A$2:$A$10, INDEX(BOM_Produits!$B$2:$G$10, 0, MATCH($A3, BOM_Produits!$B$1:$G$1, 0)), 0) * INDEX(Plan_Production!$B$2:$M$10, 0, VALUE(SUBSTITUTE(H$1, "P", ""))) )} -> 3085 | I3: {=SUMPRODUCT( (Plan_Production!$A$2:$A$10<>"") * _xlfn.XLOOKUP(Plan_Production!$A$2:$A$10, BOM_Produits!$A$2:$A$10, INDEX(BOM_Produits!$B$2:$G$10, 0, MATCH($A3, BOM_Produits!$B$1:$G$1, 0)), 0) * INDEX(Plan_Production!$B$2:$M$10, 0, VALUE(SUBSTITUTE(I$1, "P", ""))) )} -> 3675 | ... M3: {=SUMPRODUCT( (Plan_Production!$A$2:$A$10<>"") * _xlfn.XLOOKUP(Plan_Production!$A$2:$A$10, BOM_Produits!$A$2:$A$10, INDEX(BOM_Produits!$B$2:$G$10, 0, MATCH($A3, BOM_Produits!$B$1:$G$1, 0)), 0) * INDEX(Plan_Production!$B$2:$M$10, 0, VALUE(SUBSTITUTE(M$1, "P", ""))) )} -> 3890
A4: Résine | B4: {=SUMPRODUCT( (Plan_Production!$A$2:$A$10<>"") * _xlfn.XLOOKUP(Plan_Production!$A$2:$A$10, BOM_Produits!$A$2:$A$10, INDEX(BOM_Produits!$B$2:$G$10, 0, MATCH($A4, BOM_Produits!$B$1:$G$1, 0)), 0) * INDEX(Plan_Production!$B$2:$M$10, 0, VALUE(SUBSTITUTE(B$1, "P", ""))) )} -> 1836 | C4: {=SUMPRODUCT( (Plan_Production!$A$2:$A$10<>"") * _xlfn.XLOOKUP(Plan_Production!$A$2:$A$10, BOM_Produits!$A$2:$A$10, INDEX(BOM_Produits!$B$2:$G$10, 0, MATCH($A4, BOM_Produits!$B$1:$G$1, 0)), 0) * INDEX(Plan_Production!$B$2:$M$10, 0, VALUE(SUBSTITUTE(C$1, "P", ""))) )} -> 2420 | D4: {=SUMPRODUCT( (Plan_Production!$A$2:$A$10<>"") * _xlfn.XLOOKUP(Plan_Production!$A$2:$A$10, BOM_Produits!$A$2:$A$10, INDEX(BOM_Produits!$B$2:$G$10, 0, MATCH($A4, BOM_Produits!$B$1:$G$1, 0)), 0) * INDEX(Plan_Production!$B$2:$M$10, 0, VALUE(SUBSTITUTE(D$1, "P", ""))) )} -> 2135 | E4: {=SUMPRODUCT( (Plan_Production!$A$2:$A$10<>"") * _xlfn.XLOOKUP(Plan_Production!$A$2:$A$10, BOM_Produits!$A$2:$A$10, INDEX(BOM_Produits!$B$2:$G$10, 0, MATCH($A4, BOM_Produits!$B$1:$G$1, 0)), 0) * INDEX(Plan_Production!$B$2:$M$10, 0, VALUE(SUBSTITUTE(E$1, "P", ""))) )} -> 2830 | F4: {=SUMPRODUCT( (Plan_Production!$A$2:$A$10<>"") * _xlfn.XLOOKUP(Plan_Production!$A$2:$A$10, BOM_Produits!$A$2:$A$10, INDEX(BOM_Produits!$B$2:$G$10, 0, MATCH($A4, BOM_Produits!$B$1:$G$1, 0)), 0) * INDEX(Plan_Production!$B$2:$M$10, 0, VALUE(SUBSTITUTE(F$1, "P", ""))) )} -> 2585 | G4: {=SUMPRODUCT( (Plan_Production!$A$2:$A$10<>"") * _xlfn.XLOOKUP(Plan_Production!$A$2:$A$10, BOM_Produits!$A$2:$A$10, INDEX(BOM_Produits!$B$2:$G$10, 0, MATCH($A4, BOM_Produits!$B$1:$G$1, 0)), 0) * INDEX(Plan_Production!$B$2:$M$10, 0, VALUE(SUBSTITUTE(G$1, "P", ""))) )} -> 2340 | H4: {=SUMPRODUCT( (Plan_Production!$A$2:$A$10<>"") * _xlfn.XLOOKUP(Plan_Production!$A$2:$A$10, BOM_Produits!$A$2:$A$10, INDEX(BOM_Produits!$B$2:$G$10, 0, MATCH($A4, BOM_Produits!$B$1:$G$1, 0)), 0) * INDEX(Plan_Production!$B$2:$M$10, 0, VALUE(SUBSTITUTE(H$1, "P", ""))) )} -> 2165 | I4: {=SUMPRODUCT( (Plan_Production!$A$2:$A$10<>"") * _xlfn.XLOOKUP(Plan_Production!$A$2:$A$10, BOM_Produits!$A$2:$A$10, INDEX(BOM_Produits!$B$2:$G$10, 0, MATCH($A4, BOM_Produits!$B$1:$G$1, 0)), 0) * INDEX(Plan_Production!$B$2:$M$10, 0, VALUE(SUBSTITUTE(I$1, "P", ""))) )} -> 2475 | ... M4: {=SUMPRODUCT( (Plan_Production!$A$2:$A$10<>"") * _xlfn.XLOOKUP(Plan_Production!$A$2:$A$10, BOM_Produits!$A$2:$A$10, INDEX(BOM_Produits!$B$2:$G$10, 0, MATCH($A4, BOM_Produits!$B$1:$G$1, 0)), 0) * INDEX(Plan_Production!$B$2:$M$10, 0, VALUE(SUBSTITUTE(M$1, "P", ""))) )} -> 2610

Sheet calcul
AA1: 1 | AB1: =SUM(_xlfn.ANCHORARRAY(AA1)) -> #REF!
AA2: 1
B9: 1060 | C9: 200
C10: =B9*C9 -> 212000
A11: ouvrié | B11: 200000 | C11: =B9*250 -> 265000
B12: 250000
A13: fibre prix unité | B13: 6 | C13: fibre recyclabe | D13: 6 | E13: en plus cela change en fonction des périodes ...
A14: resine prix unité | B14: 1.25 | C14: resine recyclabe | D14: 1.626
A15: coût ski elite | B15: =B19*$B$13+C19*$B$14 -> 101
A16: coũt ski 2000 | B16: =B20*$B$13+C20*$B$14 -> 53.5
A17: coût raquette | B17: =B21*$B$13+C21*$B$14 -> 36.25
A19: ski elite | B19: 16 | C19: 4 | AB19: 2
A20: ski 2000 | B20: 6 | C20: 14
A21: raquette | B21: 5 | C21: 5 | Q21: DECISION | S21: RESTE | U21: REALITE
A22: Production ski elite | B22: fibre K | C22: resine K | D22: Production ski 2000 | E22: fibre K | F22: resine K | G22: Production raquette | H22: fibre K | I22: resine K | J22: stock fibre K | K22: stock resine K | L22: TOTAL Fibre | M22: TOTAL Résine | N22: TOTAL PRIX € | O22: %fibre recyclé | P22: %résine recyclé | Q22: DECISION fibre K | R22: DECISION résine K | S22: RESTE fibre K | T22: RESTE résine K | U22: REALITE fibre K | V22: REALITE résine K
A23: 180 | B23: =$A23*$B$19 -> 2880 | C23: =$A23*$C$19 -> 720 | D23: 20 | E23: =$D23*$B$20 -> 120 | F23: =$D23*$C$20 -> 280 | G23: 0 | H23: =$G23*$B$21 -> 0 | I23: =$G23*$C$21 -> 0 | J23: 1200 | K23: 150 | L23: =B23+E23+H23 -J23 -> 1800 | M23: =C23+F23+I23 -K23 -> 850 | N23: =(1-O23)*(L23*$B$13) + O23*(L23*$D$13) + (1-P23)*M23*$B$14 + P23*(M23*$D$14) -> 11862.5 | O23: 0 | P23: 0 | Q23: 1900 | R23: 900 | S23: =Q23-L23 -> 100 | T23: =R23-M23 -> 50 | U23: 100 | V23: 50
A24: 120 | B24: =$A24*$B$19 -> 1920 | C24: =$A24*$C$19 -> 480 | D24: 90 | E24: =$D24*$B$20 -> 540 | F24: =$D24*$C$20 -> 1260 | G24: 37 | H24: =$G24*$B$21 -> 185 | I24: =$G24*$C$21 -> 185 | J24: 100 | K24: 50 | L24: =B24+E24+H24 -J24 -> 2545 | M24: =C24+F24+I24 -K24 -> 1875 | N24: =(1-O24)*(L24*$B$13) + O24*(L24*$D$13) + (1-P24)*M24*$B$14 + P24*(M24*$D$14) -> 17613.75 | O24: 0 | P24: 0 | Q24: 2800 | R24: 2900 | S24: =Q24-L24 -> 255 | T24: =R24-M24 -> 1025 | U24: 255 | V24: 1025
A25: 122 | B25: =$A25*$B$19 -> 1952 | C25: =$A25*$C$19 -> 488 | D25: 80 | E25: =$D25*$B$20 -> 480 | F25: =$D25*$C$20 -> 1120 | G25: 34 | H25: =$G25*$B$21 -> 170 | I25: =$G25*$C$21 -> 170 | J25: 255 | K25: 1025 | L25: =B25+E25+H25 -J25 -> 2347 | M25: =C25+F25+I25 -K25 -> 753 | N25: =(1-O25)*(L25*$B$13) + O25*(L25*$D$13) + (1-P25)*M25*$B$14 + P25*(M25*$D$14) -> 15023.25 | O25: 0 | P25: 0 | Q25: 4200 | R25: 600 | S25: =Q25-L25 -> 1853 | T25: =R25-M25 -> -153 | U25: 1853 | V25: 0
A26: 103 | B26: =$A26*$B$19 -> 1648 | C26: =$A26*$C$19 -> 412 | D26: 104 | E26: =$D26*$B$20 -> 624 | F26: =$D26*$C$20 -> 1456 | G26: 58 | H26: =$G26*$B$21 -> 290 | I26: =$G26*$C$21 -> 290 | J26: 1853 | K26: 0 | L26: =B26+E26+H26 -J26 -> 709 | M26: =C26+F26+I26 -K26 -> 2158 | N26: =(1-O26)*(L26*$B$13) + O26*(L26*$D$13) + (1-P26)*M26*$B$14 + P26*(M26*$D$14) -> 6951.5 | O26: 0 | P26: 0 | Q26: 900 | R26: 2100 | S26: =Q26-L26 -> 191 | T26: =R26-M26 -> -58 | U26: 191 | V26: 0
A27: 125 | B27: =$A27*$B$19 -> 2000 | C27: =$A27*$C$19 -> 500 | D27: 106 | E27: =$D27*$B$20 -> 636 | F27: =$D27*$C$20 -> 1484 | G27: 34 | H27: =$G27*$B$21 -> 170 | I27: =$G27*$C$21 -> 170 | J27: 191 | K27: 0 | L27: =B27+E27+H27 -J27 -> 2615 | M27: =C27+F27+I27 -K27 -> 2154 | N27: =(1-O27)*(L27*$B$13) + O27*(L27*$D$13) + (1-P27)*M27*$B$14 + P27*(M27*$D$14) -> 18625.471 | O27: 0.1 | P27: 0.3 | Q27: 2700 | R27: 2500 | S27: =Q27-L27 -> 85 | T27: =R27-M27 -> 346 | U27: 85 | V27: 346
A28: 120 | B28: =$A28*$B$19 -> 1920 | C28: =$A28*$C$19 -> 480 | D28: 79 | E28: =$D28*$B$20 -> 474 | F28: =$D28*$C$20 -> 1106 | G28: 50 | H28: =$G28*$B$21 -> 250 | I28: =$G28*$C$21 -> 250 | J28: 85 | K28: 346 | L28: =B28+E28+H28 -J28 -> 2559 | M28: =C28+F28+I28 -K28 -> 1490 | N28: =(1-O28)*(L28*$B$13) + O28*(L28*$D$13) + (1-P28)*M28*$B$14 + P28*(M28*$D$14) -> 17384.572 | O28: 0.1 | P28: 0.3 | Q28: 2400 | R28: 1700 | S28: =Q28-L28 -> -159 | T28: =R28-M28 -> 210 | U28: 0 | V28: 210
A31: =_xlfn.TEXTJOIN(";", FALSE, A22:V22) -> Production ski elite ;fibre K;resine K;Production ski 2000 ;fibre K;resine K;Production raquette;fibre K;resine K;stock fibre K;stock resine K;TOTAL Fibre;TOTAL Résine;TOTAL PRIX €;%fibre recyclé;%résine recyclé;DECISION fibre K;DECISION résine K;RESTE fibre K;RESTE résine K;REALITE fibre K;REALITE résine K
A32: =_xlfn.TEXTJOIN(";", FALSE, A28:V28) -> 120;1920;480;79;474;1106;50;250;250;85;346;2559;1490;17384,572;0,1;0,3;2400;1700;-159;210;0;210
A44: 16 | B44: 240
A45: 20 | B45: 190 | C45: 104 | D45: =(B45+A45)*C45 -> 21840
A46: 0 | B46: 169 | C46: 58 | D46: =(B46+A46)*C46 -> 9802
D47: =SUM(D45:D46) -> 31642 | F47: =D47-56860 -> -25218

Sheet Besoins_Coûts
A1: COÛTS (€) | B1: {="P"&_xlfn.SEQUENCE(1, PARAMETRES_GENERAUX!$B$2, PARAMETRES_GENERAUX!$B$3)} -> P1 | C1: P2 | D1: P3 | E1: P4 | F1: P5 | G1: P6 | H1: P7 | I1: P8 | J1: P9 | K1: P10 | L1: P11 | M1: P12
A2: TOTAL | B2: =SUM(B3:INDEX(B:B, COUNTA(Param_MP!$A:$A)+1)) -> 18498.301 | C2: =SUM(C3:INDEX(C:C, COUNTA(Param_MP!$A:$A)+1)) -> 26166.976 | D2: =SUM(D3:INDEX(D:D, COUNTA(Param_MP!$A:$A)+1)) -> 22360.328 | E2: =SUM(E3:INDEX(E:E, COUNTA(Param_MP!$A:$A)+1)) -> 29690.224 | F2: =SUM(F3:INDEX(F:F, COUNTA(Param_MP!$A:$A)+1)) -> 26906.088 | G2: =SUM(G3:INDEX(G:G, COUNTA(Param_MP!$A:$A)+1)) -> 24121.952 | H2: =SUM(H3:INDEX(H:H, COUNTA(Param_MP!$A:$A)+1)) -> 21614.712 | I2: =SUM(I3:INDEX(I:I, COUNTA(Param_MP!$A:$A)+1)) -> 25606.68 | J2: =SUM(J3:INDEX(J:J, COUNTA(Param_MP!$A:$A)+1)) -> 28390.816 | K2: =SUM(K3:INDEX(K:K, COUNTA(Param_MP!$A:$A)+1)) -> 31360.272 | L2: =SUM(L3:INDEX(L:L, COUNTA(Param_MP!$A:$A)+1)) -> 29875.544 | M2: =SUM(M3:INDEX(M:M, COUNTA(Param_MP!$A:$A)+1)) -> 27091.408
A3: {=_xlfn._xlws.FILTER(Param_MP!A2:A100, Param_MP!A2:A100<>"", "")} -> Fibre | B3: {=_xlfn.LET( _xlpm.mp, $A3, _xlpm.p, VALUE(SUBSTITUTE(B$1, "P", "")), _xlpm.besoin, Besoins_Quantités!B3, _xlpm.prixVirgin, INDEX(Prix_MP!$B$2:$M$5, MATCH(_xlpm.mp, Prix_MP!$A$2:$A$5, 0), _xlpm.p), _xlpm.prixRecycle, INDEX(Prix_MP!$B$7:$M$16, MATCH(_xlpm.mp, Prix_MP!$A$7:$A$16, 0), _xlpm.p), _xlpm.pctRecycle, INDEX(Mix_MP!$B$2:$M$7, MATCH(_xlpm.mp, Mix_MP!$A$2:$A$7, 0), _xlpm.p), _xlpm.prixMoyen, (1 - _xlpm.pctRecycle) * _xlpm.prixVirgin + _xlpm.pctRecycle * _xlpm.prixRecycle, _xlpm.besoin * _xlpm.prixMoyen )} -> 15996.2 | C3: {=_xlfn.LET( _xlpm.mp, $A3, _xlpm.p, VALUE(SUBSTITUTE(C$1, "P", "")), _xlpm.besoin, Besoins_Quantités!C3, _xlpm.prixVirgin, INDEX(Prix_MP!$B$2:$M$5, MATCH(_xlpm.mp, Prix_MP!$A$2:$A$5, 0), _xlpm.p), _xlpm.prixRecycle, INDEX(Prix_MP!$B$7:$M$16, MATCH(_xlpm.mp, Prix_MP!$A$7:$A$16, 0), _xlpm.p), _xlpm.pctRecycle, INDEX(Mix_MP!$B$2:$M$7, MATCH(_xlpm.mp, Mix_MP!$A$2:$A$7, 0), _xlpm.p), _xlpm.prixMoyen, (1 - _xlpm.pctRecycle) * _xlpm.prixVirgin + _xlpm.pctRecycle * _xlpm.prixRecycle, _xlpm.besoin * _xlpm.prixMoyen )} -> 22869 | D3: {=_xlfn.LET( _xlpm.mp, $A3, _xlpm.p, VALUE(SUBSTITUTE(D$1, "P", "")), _xlpm.besoin, Besoins_Quantités!D3, _xlpm.prixVirgin, INDEX(Prix_MP!$B$2:$M$5, MATCH(_xlpm.mp, Prix_MP!$A$2:$A$5, 0), _xlpm.p), _xlpm.prixRecycle, INDEX(Prix_MP!$B$7:$M$16, MATCH(_xlpm.mp, Prix_MP!$A$7:$A$16, 0), _xlpm.p), _xlpm.pctRecycle, INDEX(Mix_MP!$B$2:$M$7, MATCH(_xlpm.mp, Mix_MP!$A$2:$A$7, 0), _xlpm.p), _xlpm.prixMoyen, (1 - _xlpm.pctRecycle) * _xlpm.prixVirgin + _xlpm.pctRecycle * _xlpm.prixRecycle, _xlpm.besoin * _xlpm.prixMoyen )} -> 19450.75 | E3: {=_xlfn.LET( _xlpm.mp, $A3, _xlpm.p, VALUE(SUBSTITUTE(E$1, "P", "")), _xlpm.besoin, Besoins_Quantités!E3, _xlpm.prixVirgin, INDEX(Prix_MP!$B$2:$M$5, MATCH(_xlpm.mp, Prix_MP!$A$2:$A$5, 0), _xlpm.p), _xlpm.prixRecycle, INDEX(Prix_MP!$B$7:$M$16, MATCH(_xlpm.mp, Prix_MP!$A$7:$A$16, 0), _xlpm.p), _xlpm.pctRecycle, INDEX(Mix_MP!$B$2:$M$7, MATCH(_xlpm.mp, Mix_MP!$A$2:$A$7, 0), _xlpm.p), _xlpm.prixMoyen, (1 - _xlpm.pctRecycle) * _xlpm.prixVirgin + _xlpm.pctRecycle * _xlpm.prixRecycle, _xlpm.besoin * _xlpm.prixMoyen )} -> 25833.5 | F3: {=_xlfn.LET( _xlpm.mp, $A3, _xlpm.p, VALUE(SUBSTITUTE(F$1, "P", "")), _xlpm.besoin, Besoins_Quantités!F3, _xlpm.prixVirgin, INDEX(Prix_MP!$B$2:$M$5, MATCH(_xlpm.mp, Prix_MP!$A$2:$A$5, 0), _xlpm.p), _xlpm.prixRecycle, INDEX(Prix_MP!$B$7:$M$16, MATCH(_xlpm.mp, Prix_MP!$A$7:$A$16, 0), _xlpm.p), _xlpm.pctRecycle, INDEX(Mix_MP!$B$2:$M$7, MATCH(_xlpm.mp, Mix_MP!$A$2:$A$7, 0), _xlpm.p), _xlpm.prixMoyen, (1 - _xlpm.pctRecycle) * _xlpm.prixVirgin + _xlpm.pctRecycle * _xlpm.prixRecycle, _xlpm.besoin * _xlpm.prixMoyen )} -> 23383.25 | G3: {=_xlfn.LET( _xlpm.mp, $A3, _xlpm.p, VALUE(SUBSTITUTE(G$1, "P", "")), _xlpm.besoin, Besoins_Quantités!G3, _xlpm.prixVirgin, INDEX(Prix_MP!$B$2:$M$5, MATCH(_xlpm.mp, Prix_MP!$A$2:$A$5, 0), _xlpm.p), _xlpm.prixRecycle, INDEX(Prix_MP!$B$7:$M$16, MATCH(_xlpm.mp, Prix_MP!$A$7:$A$16, 0), _xlpm.p), _xlpm.pctRecycle, INDEX(Mix_MP!$B$2:$M$7, MATCH(_xlpm.mp, Mix_MP!$A$2:$A$7, 0), _xlpm.p), _xlpm.prixMoyen, (1 - _xlpm.pctRecycle) * _xlpm.prixVirgin + _xlpm.pctRecycle * _xlpm.prixRecycle, _xlpm.besoin * _xlpm.prixMoyen )} -> 20933 | H3: {=_xlfn.LET( _xlpm.mp, $A3, _xlpm.p, VALUE(SUBSTITUTE(H$1, "P", "")), _xlpm.besoin, Besoins_Quantités!H3, _xlpm.prixVirgin, INDEX(Prix_MP!$B$2:$M$5, MATCH(_xlpm.mp, Prix_MP!$A$2:$A$5, 0), _xlpm.p), _xlpm.prixRecycle, INDEX(Prix_MP!$B$7:$M$16, MATCH(_xlpm.mp, Prix_MP!$A$7:$A$16, 0), _xlpm.p), _xlpm.pctRecycle, INDEX(Mix_MP!$B$2:$M$7, MATCH(_xlpm.mp, Mix_MP!$A$2:$A$7, 0), _xlpm.p), _xlpm.prixMoyen, (1 - _xlpm.pctRecycle) * _xlpm.prixVirgin + _xlpm.pctRecycle * _xlpm.prixRecycle, _xlpm.besoin * _xlpm.prixMoyen )} -> 18664.25 | I3: {=_xlfn.LET( _xlpm.mp, $A3, _xlpm.p, VALUE(SUBSTITUTE(I$1, "P", "")), _xlpm.besoin, Besoins_Quantités!I3, _xlpm.prixVirgin, INDEX(Prix_MP!$B$2:$M$5, MATCH(_xlpm.mp, Prix_MP!$A$2:$A$5, 0), _xlpm.p), _xlpm.prixRecycle, INDEX(Prix_MP!$B$7:$M$16, MATCH(_xlpm.mp, Prix_MP!$A$7:$A$16, 0), _xlpm.p), _xlpm.pctRecycle, INDEX(Mix_MP!$B$2:$M$7, MATCH(_xlpm.mp, Mix_MP!$A$2:$A$7, 0), _xlpm.p), _xlpm.prixMoyen, (1 - _xlpm.pctRecycle) * _xlpm.prixVirgin + _xlpm.pctRecycle * _xlpm.prixRecycle, _xlpm.besoin * _xlpm.prixMoyen )} -> 22233.75 | ... M3: {=_xlfn.LET( _xlpm.mp, $A3, _xlpm.p, VALUE(SUBSTITUTE(M$1, "P", "")), _xlpm.besoin, Besoins_Quantités!M3, _xlpm.prixVirgin, INDEX(Prix_MP!$B$2:$M$5, MATCH(_xlpm.mp, Prix_MP!$A$2:$A$5, 0), _xlpm.p), _xlpm.prixRecycle, INDEX(Prix_MP!$B$7:$M$16, MATCH(_xlpm.mp, Prix_MP!$A$7:$A$16, 0), _xlpm.p), _xlpm.pctRecycle, INDEX(Mix_MP!$B$2:$M$7, MATCH(_xlpm.mp, Mix_MP!$A$2:$A$7, 0), _xlpm.p), _xlpm.prixMoyen, (1 - _xlpm.pctRecycle) * _xlpm.prixVirgin + _xlpm.pctRecycle * _xlpm.prixRecycle, _xlpm.besoin * _xlpm.prixMoyen )} -> 23534.5
A4: Résine | B4: {=_xlfn.LET( _xlpm.mp, $A4, _xlpm.p, VALUE(SUBSTITUTE(B$1, "P", "")), _xlpm.besoin, Besoins_Quantités!B4, _xlpm.prixVirgin, INDEX(Prix_MP!$B$2:$M$5, MATCH(_xlpm.mp, Prix_MP!$A$2:$A$5, 0), _xlpm.p), _xlpm.prixRecycle, INDEX(Prix_MP!$B$7:$M$16, MATCH(_xlpm.mp, Prix_MP!$A$7:$A$16, 0), _xlpm.p), _xlpm.pctRecycle, INDEX(Mix_MP!$B$2:$M$7, MATCH(_xlpm.mp, Mix_MP!$A$2:$A$7, 0), _xlpm.p), _xlpm.prixMoyen, (1 - _xlpm.pctRecycle) * _xlpm.prixVirgin + _xlpm.pctRecycle * _xlpm.prixRecycle, _xlpm.besoin * _xlpm.prixMoyen )} -> 2502.1008 | C4: {=_xlfn.LET( _xlpm.mp, $A4, _xlpm.p, VALUE(SUBSTITUTE(C$1, "P", "")), _xlpm.besoin, Besoins_Quantités!C4, _xlpm.prixVirgin, INDEX(Prix_MP!$B$2:$M$5, MATCH(_xlpm.mp, Prix_MP!$A$2:$A$5, 0), _xlpm.p), _xlpm.prixRecycle, INDEX(Prix_MP!$B$7:$M$16, MATCH(_xlpm.mp, Prix_MP!$A$7:$A$16, 0), _xlpm.p), _xlpm.pctRecycle, INDEX(Mix_MP!$B$2:$M$7, MATCH(_xlpm.mp, Mix_MP!$A$2:$A$7, 0), _xlpm.p), _xlpm.prixMoyen, (1 - _xlpm.pctRecycle) * _xlpm.prixVirgin + _xlpm.pctRecycle * _xlpm.prixRecycle, _xlpm.besoin * _xlpm.prixMoyen )} -> 3297.976 | D4: {=_xlfn.LET( _xlpm.mp, $A4, _xlpm.p, VALUE(SUBSTITUTE(D$1, "P", "")), _xlpm.besoin, Besoins_Quantités!D4, _xlpm.prixVirgin, INDEX(Prix_MP!$B$2:$M$5, MATCH(_xlpm.mp, Prix_MP!$A$2:$A$5, 0), _xlpm.p), _xlpm.prixRecycle, INDEX(Prix_MP!$B$7:$M$16, MATCH(_xlpm.mp, Prix_MP!$A$7:$A$16, 0), _xlpm.p), _xlpm.pctRecycle, INDEX(Mix_MP!$B$2:$M$7, MATCH(_xlpm.mp, Mix_MP!$A$2:$A$7, 0), _xlpm.p), _xlpm.prixMoyen, (1 - _xlpm.pctRecycle) * _xlpm.prixVirgin + _xlpm.pctRecycle * _xlpm.prixRecycle, _xlpm.besoin * _xlpm.prixMoyen )} -> 2909.578 | E4: {=_xlfn.LET( _xlpm.mp, $A4, _xlpm.p, VALUE(SUBSTITUTE(E$1, "P", "")), _xlpm.besoin, Besoins_Quantités!E4, _xlpm.prixVirgin, INDEX(Prix_MP!$B$2:$M$5, MATCH(_xlpm.mp, Prix_MP!$A$2:$A$5, 0), _xlpm.p), _xlpm.prixRecycle, INDEX(Prix_MP!$B$7:$M$16, MATCH(_xlpm.mp, Prix_MP!$A$7:$A$16, 0), _xlpm.p), _xlpm.pctRecycle, INDEX(Mix_MP!$B$2:$M$7, MATCH(_xlpm.mp, Mix_MP!$A$2:$A$7, 0), _xlpm.p), _xlpm.prixMoyen, (1 - _xlpm.pctRecycle) * _xlpm.prixVirgin + _xlpm.pctRecycle * _xlpm.prixRecycle, _xlpm.besoin * _xlpm.prixMoyen )} -> 3856.724 | F4: {=_xlfn.LET( _xlpm.mp, $A4, _xlpm.p, VALUE(SUBSTITUTE(F$1, "P", "")), _xlpm.besoin, Besoins_Quantités!F4, _xlpm.prixVirgin, INDEX(Prix_MP!$B$2:$M$5, MATCH(_xlpm.mp, Prix_MP!$A$2:$A$5, 0), _xlpm.p), _xlpm.prixRecycle, INDEX(Prix_MP!$B$7:$M$16, MATCH(_xlpm.mp, Prix_MP!$A$7:$A$16, 0), _xlpm.p), _xlpm.pctRecycle, INDEX(Mix_MP!$B$2:$M$7, MATCH(_xlpm.mp, Mix_MP!$A$2:$A$7, 0), _xlpm.p), _xlpm.prixMoyen, (1 - _xlpm.pctRecycle) * _xlpm.prixVirgin + _xlpm.pctRecycle * _xlpm.prixRecycle, _xlpm.besoin * _xlpm.prixMoyen )} -> 3522.838 | G4: {=_xlfn.LET( _xlpm.mp, $A4, _xlpm.p, VALUE(SUBSTITUTE(G$1, "P", "")), _xlpm.besoin, Besoins_Quantités!G4, _xlpm.prixVirgin, INDEX(Prix_MP!$B$2:$M$5, MATCH(_xlpm.mp, Prix_MP!$A$2:$A$5, 0), _xlpm.p), _xlpm.prixRecycle, INDEX(Prix_MP!$B$7:$M$16, MATCH(_xlpm.mp, Prix_MP!$A$7:$A$16, 0), _xlpm.p), _xlpm.pctRecycle, INDEX(Mix_MP!$B$2:$M$7, MATCH(_xlpm.mp, Mix_MP!$A$2:$A$7, 0), _xlpm.p), _xlpm.prixMoyen, (1 - _xlpm.pctRecycle) * _xlpm.prixVirgin + _xlpm.pctRecycle * _xlpm.prixRecycle, _xlpm.besoin * _xlpm.prixMoyen )} -> 3188.952 | H4: {=_xlfn.LET( _xlpm.mp, $A4, _xlpm.p, VALUE(SUBSTITUTE(H$1, "P", "")), _xlpm.besoin, Besoins_Quantités!H4, _xlpm.prixVirgin, INDEX(Prix_MP!$B$2:$M$5, MATCH(_xlpm.mp, Prix_MP!$A$2:$A$5, 0), _xlpm.p), _xlpm.prixRecycle, INDEX(Prix_MP!$B$7:$M$16, MATCH(_xlpm.mp, Prix_MP!$A$7:$A$16, 0), _xlpm.p), _xlpm.pctRecycle, INDEX(Mix_MP!$B$2:$M$7, MATCH(_xlpm.mp, Mix_MP!$A$2:$A$7, 0), _xlpm.p), _xlpm.prixMoyen, (1 - _xlpm.pctRecycle) * _xlpm.prixVirgin + _xlpm.pctRecycle * _xlpm.prixRecycle, _xlpm.besoin * _xlpm.prixMoyen )} -> 2950.462 | I4: {=_xlfn.LET( _xlpm.mp, $A4, _xlpm.p, VALUE(SUBSTITUTE(I$1, "P", "")), _xlpm.besoin, Besoins_Quantités!I4, _xlpm.prixVirgin, INDEX(Prix_MP!$B$2:$M$5, MATCH(_xlpm.mp, Prix_MP!$A$2:$A$5, 0), _xlpm.p), _xlpm.prixRecycle, INDEX(Prix_MP!$B$7:$M$16, MATCH(_xlpm.mp, Prix_MP!$A$7:$A$16, 0), _xlpm.p), _xlpm.pctRecycle, INDEX(Mix_MP!$B$2:$M$7, MATCH(_xlpm.mp, Mix_MP!$A$2:$A$7, 0), _xlpm.p), _xlpm.prixMoyen, (1 - _xlpm.pctRecycle) * _xlpm.prixVirgin + _xlpm.pctRecycle * _xlpm.prixRecycle, _xlpm.besoin * _xlpm.prixMoyen )} -> 3372.93 | ... M4: {=_xlfn.LET( _xlpm.mp, $A4, _xlpm.p, VALUE(SUBSTITUTE(M$1, "P", "")), _xlpm.besoin, Besoins_Quantités!M4, _xlpm.prixVirgin, INDEX(Prix_MP!$B$2:$M$5, MATCH(_xlpm.mp, Prix_MP!$A$2:$A$5, 0), _xlpm.p), _xlpm.prixRecycle, INDEX(Prix_MP!$B$7:$M$16, MATCH(_xlpm.mp, Prix_MP!$A$7:$A$16, 0), _xlpm.p), _xlpm.pctRecycle, INDEX(Mix_MP!$B$2:$M$7, MATCH(_xlpm.mp, Mix_MP!$A$2:$A$7, 0), _xlpm.p), _xlpm.prixMoyen, (1 - _xlpm.pctRecycle) * _xlpm.prixVirgin + _xlpm.pctRecycle * _xlpm.prixRecycle, _xlpm.besoin * _xlpm.prixMoyen )} -> 3556.908

Sheet PARAMETRES_GENERAUX
A1: Paramètre | B1: Valeur
A2: Période_Max | B2: 12
A3: Période_Début | B3: 1
A4: Unité_Production | B4: KU
A5: Devise | B5: €
